<mujoco>
  <include file="../mujoco_model/basic_scene.xml" />

  <extension>
    <plugin plugin="mujoco.elasticity.cable"/>
    <plugin plugin="mujoco.pid">
      <instance name="pid">
        <config key="kp" value="400.0"/>
        <config key="ki" value="40"/>
        <config key="kd" value="4"/>
        <config key="slewmax" value="3" />
        <config key="imax" value="1"/>
      </instance>
    </plugin>
  </extension>

  <option gravity="0 0 0" integrator="implicitfast"/>

  <visual>
    <global offheight="2160" offwidth="3840"/>
    <quality offsamples="8"/>
  </visual>

  <worldbody>
    <light diffuse=".8 .8 .8" pos="0 0 5" dir="0 0 -1"/>
    <geom type="plane" size="0 0 0.03" material="matplane" rgba="1 1 1 1" />
    <geom type="plane" pos="0 0 0.002" axisangle="1 0 0 180" size="0 0 0.03" material="matplane" rgba="1 1 1 1" />
    <camera name="whisker_cam_3" pos="0 0.1 0.4" />
    
    <body name="whisker_base" pos="-0.005 0.1 0.001" axisangle="1 0 0 90">
      <joint name="whisker_joint_x" type="slide" axis="0 0 1" damping="10" stiffness="0" armature="0.1"/>
      <joint name="whisker_joint_y" type="slide" axis="1 0 0" damping="10" stiffness="0" armature="0.1"/>
      <joint name="whisker_joint_z" type="hinge" axis="0 1 0" damping="1" armature="0.01"/>
      <!--"contype="0" conaffinity="0"": used to avoid the unknowable vibration of whisker when contacting the whisker base-->
      <geom type="cylinder" size="0.005 0.005" rgba=".8 .3 .1 .5" mass="0.1" contype="0" conaffinity="0" />
      <camera name="whisker_cam" pos="0 0.25 0.05" xyaxes="1 0 0 0 0 -1"/>
      <camera name="whisker_cam_2" pos="-0.15 0 0.05" xyaxes="0 0 1 0 1 0"/>
      <site name="vel_sensor"/>

      <body name="whisker_body">
        <!-- xqy: joint still not sure -->
        <joint name="base2whisker_z" type="hinge" axis="0 1 0" damping="0.01" stiffness ="1" armature="0.00001"/>
        <geom type="cylinder" size="0.000125 0.01" rgba=".8 .3 .7 1" mass="0.005" contype="0" conaffinity="0" />
        <!-- <site name="force_sensor"/> -->

        <composite prefix="whisker" type="cable" curve="0 0 s" count="40 1 1"
          size="0.1 0 0" initial="none">
          <plugin plugin="mujoco.elasticity.cable">
            <config key="twist" value="40e9"/>
            <config key="bend" value="100e9"/>  <!-- https://www.ulbrich.com/alloys/nitinol-wire-astm-f2063/ -->
            <config key="vmax" value="0.001"/>
          </plugin>
          <!-- xqy: joint still not sure -->
          <joint kind="main" damping="0.0001" armature="0.00001"/> 
          <geom type="capsule" size=".000125" rgba=".8 .3 .1 1" condim="1" density="6450"/>
        </composite>
      </body>

    </body>

    <!-- <body name="beam_base" pos="-0.07 0.07 0.075" axisangle="1 0 0 90">
      <joint name="beam_joint" type="slide" axis="1 0 0" damping="100" />
      <geom type="cylinder" size="0.005 0.005" rgba=".8 .3 .1 1" mass="0.1" />

      <body name="beam">
        <joint name="base2beam" type="hinge" axis="0 1 0" stiffness ="10" damping="0.1" armature="0.01"/>
        <geom type="cylinder" pos="0 0 0.05" size="0.00015 0.05" rgba=".8 .2 .1 1" density="4650"/>
      </body>     
    </body> -->

    <body name="around_circle" pos="0 0 0">
      <geom type="cylinder" size="0.05 0.35" pos="0 -0.05 0"  rgba=".8 .4 .1 1" condim="1"/>
    </body>

  </worldbody>



  <actuator>
    <!-- velocity control -->
    <velocity joint="whisker_joint_x" name="whisker_move_vel_x"/>
    <velocity joint="whisker_joint_y" name="whisker_move_vel_y"/>
    <plugin joint="whisker_joint_z" plugin="mujoco.pid" instance="pid" />
    <!-- <position joint="beam_joint" name="beam_move" ctrlrange="-0.3 4" ctrllimited="true" kp="400" /> -->
  </actuator>

  <sensor>
    <jointpos joint="base2whisker_z" name="base2whisker_z"/>

    <velocimeter site="vel_sensor" name="vel_sensor"/>

    <jointpos joint="whisker_joint_x" name="whisker_joint_x"/>
    <jointpos joint="whisker_joint_y" name="whisker_joint_y"/>
    <jointpos joint="whisker_joint_z" name="whisker_joint_z"/>

    <framepos objtype="site" objname="whiskerS_last" reftype="site" refname="vel_sensor" name="tip_pos"/>
    <gyro site="vel_sensor" name="gyro_sensor"/>

  </sensor>

</mujoco>
